Workbook

Sheet 說明
A1: 法術書：職業與學派整理
A3: 這份活頁簿做什麼 | B3: 把資料裡 207 種職業寫法、16 筆有問題的等級資料、34 筆有疑義的學派，整理成之後要建立的「標準職業表」與學派對照。
A4: 你要做的事 | B4: 只需要修改黃色欄位。每一列都已經填好我的建議；同意就不用動，不同意就直接改。有疑問寫在「你的備註」。
A5: 黃色欄位 | B5: 可以修改的欄位。其他欄位是從資料庫整理出來的參考資訊，請不要改。
A6: 多個名稱 | B6: 一個寫法對應多個標準名稱時，用全形分號「；」分隔，例如「術士；法師」。
A8: 工作表
A9: 職業對照 | B9: 資料裡每一種職業寫法（共 207 種）。「類別」填：職業、領域、其他、等級修正、刪除。「標準名稱」填它對應到標準職業表裡的哪個名稱。
A10: 等級修正 | B10: 職業與等級黏在一起、或混入其他書版本的 15 個法術。「建議正確等級」會取代這個法術目前全部的等級資料，格式：職業 等級；職業 等級。
A11: 學派疑義 | B11: 自動規則分不出來、跨學派、或疑似誤譯的法術。其餘法術會依規則自動歸類，不在這張表裡。「建議學派」可填多個，用「；」分隔。
A12: 標準職業表 | B12: 整理後的最終清單，也就是之後 app 裡要建立的那張表。新增標準名稱時在這裡加一列；「對應寫法數」與「等級資料筆數」會自動計算。
A14: 範例 | B14: 職業對照中「德魯依」這一列：類別＝領域 → 改成「職業」；標準名稱＝「德魯伊」。代表「德魯依」是「德魯伊」的另一種寫法。
A16: 標示「待確認」 | B16: 是我不確定的歸類（例如巫覡、修驗者的英文對應，或兩個領域是否相同），特別需要你看一下。
A17: 學派自動歸類結果 | B17: 以下學派由規則自動判定，不需要檢查：變化 647 筆、咒法 370 筆、塑能 327 筆、防護 277 筆、死靈 233 筆、惑控 167 筆、預言 164 筆、幻術 125 筆、通用 16 筆

Sheet 職業對照
A1: 編號 | B1: 原始寫法 | C1: 等級資料筆數 | D1: 出現的等級 | E1: 例子 | F1: 類別 | G1: 標準名稱 | H1: 建議說明 | I1: 你的備註
A2: 1 | B2: 術士/法師 | C2: 1191 | D2: 0,1,2,3,4,5,6,7,8,9 | E2: 底棲魔魚詛咒、法力吸收 | F2: 職業 | G2: 術士；法師 | H2: 拆成術士與法師兩個職業
A3: 3 | B3: 牧師 | C3: 713 | D3: 0,1,2,3,4,5,6,7,8,9 | E3: 深淵軍團、由畏生敬 | F3: 職業 | G3: 牧師
A4: 16 | B4: 德魯伊 | C4: 510 | D4: 0,1,2,3,4,5,6,7,8,9 | E4: 空氣呼吸術、淩空而行 | F4: 職業 | G4: 德魯伊
A5: 4 | B5: 吟游詩人 | C5: 372 | D5: 0,1,2,3,4,5,6 | E5: 加速運動、由畏生敬 | F5: 職業 | G5: 吟遊詩人
A6: 20 | B6: 聖武士 | C6: 146 | D6: 1,2,3,4 | E6: 陣營靈光、天使之鎧 | F6: 職業 | G6: 聖武士
A7: 10 | B7: 巡林客 | C7: 119 | D7: 1,2,3,4 | E7: 空中警報、魔法警報 | F7: 職業 | G7: 遊俠
A8: 7 | B8: 巫覡 | C8: 97 | D8: 1,2,3,4,5,6,7,8,9 | E8: 精准術、精金之翼 | F8: 職業 | G8: 巫覡
A9: 12 | B9: 德魯依 | C9: 80 | D9: 1,2,3,4,5,6,7,8,9 | E9: 授予苦痛、修改機運 | F9: 職業 | G9: 德魯伊
A10: 5 | B10: 遊俠 | C10: 66 | D10: 1,2,3,4 | E10: 加速運動、陣營之牙 | F10: 職業 | G10: 遊俠
A11: 2 | B11: 刺客 | C11: 64 | D11: 1,2,3,4 | E11: 武器吸收、不定型體 | F11: 職業 | G11: 刺客
A12: 33 | B12: 法師/術士 | C12: 53 | D12: 1,2,3,4,5,6,7,9 | E12: 極地迷霧、血刃術 | F12: 職業 | G12: 術士；法師 | H12: 拆成術士與法師兩個職業
A13: 95 | B13: 詩人 | C13: 31 | D13: 0,1,2,3,4,5,6 | E13: 信任危機、自大狂 | F13: 職業 | G13: 吟遊詩人
A14: 34 | B14: 聖潔 | C14: 29 | D14: 1,2,3,4,5,6,7,8,9 | E14: 終焉聖戰、厄亞艾拉的光輝炸裂 | F14: 其他 | G14: 聖潔 | H14: 《崇善之書》的聖潔法術類別，不是職業 | I14: 這種奇怪的職業都丟到其他
A15: 6 | B15: 戰法師 | C15: 23 | D15: 1,2,4,5 | E15: 精准術、電弧術 | F15: 職業 | G15: 戰法師
A16: 36 | B16: 和平使者 | C16: 22 | D16: 1,2,3,4,5,6,7,9 | E16: 神性型貌、高等神性型貌 | F16: 職業 | G16: 和平使者
A17: 180 | B17: 法師/巫師 | C17: 22 | D17: 1,2,3,4,5,8,9 | E17: 陰影面具、陰影輝光 | F17: 職業 | G17: 術士；法師 | H17: 拆成術士與法師兩個職業
A18: 47 | B18: 暮刃 | C18: 21 | D18: 1,2,3,4,5 | E18: 畢格比強襲拳、畢格比跌拌掌 | F18: 職業 | G18: 暮刃
A19: 19 | B19: 暗黑衛士 | C19: 19 | D19: 1,2,3,4 | E19: 陣營靈光、血刃術 | F19: 職業 | G19: 暗黑衛士
A20: 64 | B20: 欺瞞者 | C20: 19 | D20: 1,2,3,4,5,6 | E20: 奪目華彩、帷幕冠冕 | F20: 職業 | G20: 欺瞞者
A21: 125 | B21: 聖騎士 | C21: 15 | D21: 1,2,3 | E21: 神助之力、忠誠之手 | F21: 職業 | G21: 聖武士
A22: 9 | B22: 魔劍客 | C22: 15 | D22: 1,2,3,4 | E22: 由畏生敬、強化魔寵 | F22: 職業 | G22: 魔劍客
A23: 32 | B23: 術士 | C23: 11 | D23: 2,3,4,5,6,7,8 | E23: 奧術融合、高等奧術融合 | F23: 職業 | G23: 術士
A24: 117 | B24: 黑暗衛士 | C24: 11 | D24: 1,2,3,4 | E24: 吸血鬼王之牙、黃金護鎧 | F24: 職業 | G24: 暗黑衛士
A25: 37 | B25: 崇善秘法師 | C25: 10 | D25: 1,4,5,6,7,9 | E25: 神性型貌、高等神性型貌 | F25: 職業 | G25: 崇善秘法師
A26: 114 | B26: 太陽 | C26: 9 | D26: 1,2,3,4,5,6,7,8,9 | E26: 忍受環境、火種術 | F26: 領域 | G26: 太陽
A27: 39 | B27: 旅行 | C27: 9 | D27: 1,2,3,4,5,6,7,8,9 | E27: 星界投射、任意門 | F27: 領域 | G27: 旅行
A28: 25 | B28: 死亡 | C28: 9 | D28: 1,2,3,4,5,6,7,8,9 | E28: 操縱死屍、驚 恐 術 | F28: 領域 | G28: 死亡
A29: 8 | B29: 水 | C29: 9 | D29: 1,2,3,4,5,6,7,8,9 | E29: 酸 霧 術、寒冰錐 | F29: 領域 | G29: 水
... A31: 85 | B31: 知識 | C31: 9 | D31: 1,2,3,4,5,6,7,8,9 | E31: 銳耳術/鷹眼術、偵測密門 | F31: 領域 | G31: 知識
A32: 28 | B32: 魔劍士 | C32: 9 | D32: 1,2,3,4 | E32: 活化武器、奧術波動 | F32: 職業 | G32: 魔劍客 | H32: 合併到魔劍客
A33: 30 | B33: 保護 | C33: 8 | D33: 1,2,4,5,6,7,8,9 | E33: 反魔場、心靈屏障 | F33: 領域 | G33: 保護
A34: 111 | B34: 土 | C34: 8 | D34: 2,3,4,5,6,7,8,9 | E34: 地震術、元素集群 | F34: 領域 | G34: 土
A35: 24 | B35: 城市 | C35: 8 | D35: 2,3,4,5,6,7,8,9 | E35: 活化城市、城樓之光 | F35: 領域 | G35: 城市
A36: 27 | B36: 植物 | C36: 8 | D36: 1,2,4,5,6,7,8,9 | E36: 活化植物、樹膚術 | F36: 領域 | G36: 植物
A37: 65 | B37: 榮耀 | C37: 8 | D37: 2,4,5,6,8,9 | E37: 光彩奪目的榮光、榮耀之矢 | F37: 領域 | G37: 榮耀
A38: 15 | B38: 機運 | C38: 8 | D38: 1,2,4,5,6,7,8,9 | E38: 援助術、破除結界 | F38: 領域 | G38: 機運
A39: 17 | B39: 氣 | C39: 8 | D39: 2,3,4,5,6,7,8,9 | E39: 淩空而行、連環閃電 | F39: 領域 | G39: 氣
A40: 26 | B40: 混亂 | C40: 8 | D40: 1,2,3,4,5,6,7,8 | E40: 活化物品、混亂之錘 | F40: 領域 | G40: 混亂 | H40: 合併了混沌
A41: 55 | B41: 邪惡 | C41: 8 | D41: 1,2,3,4,5,6,7,8 | E41: 瀆神之語、喚起死靈 | F41: 領域 | G41: 邪惡
...

Sheet 等級修正
A1: 法術 | B1: 英文名稱 | C1: 原文的等級行 | D1: 目前資料庫裡的等級 | E1: 建議正確等級 | F1: 說明 | G1: 你的備註
A2: 偵測探知 | B2: Detect Scrying | C2: 等級：吟游詩人 4 術士/法師 4 | D2: 吟游詩人 4 術士/法師 4 | E2: 吟遊詩人 4；術士 4；法師 4 | F2: 原文三個職業被合成一筆，缺了術士與法師
A3: 水龍卷 | B3: Waterspout | C3: 等級：德魯伊 7（風暴之書）海洋領域 7，術士/法師 7 | D3: 術士/法師 7；德魯伊 7（風暴之書）海洋領域 7 | E3: 德魯伊 7；海洋 7；術士 7；法師 7 | F3: 德魯伊與海洋領域被合成一筆
A4: 能量旋渦 | B4: Energy Vortex | C4: 等級：牧師 3，德魯依 3（完美神力牧師 4，德魯依 4） | D4: 牧師 3；德魯依 3（完美神力牧師 4 | E4: 牧師 3；德魯伊 3 | F4: 括號內是《完美神力》的不同等級，不採用
A5: 血流如注 | B5: Bleed | C5: 等級：暗黑衛士 4.牧師 5，德魯伊 5 | D5: 德魯伊 5；暗黑衛士 4.牧師 5 | E5: 暗黑衛士 4；牧師 5；德魯伊 5 | F5: 暗黑衛士與牧師被合成一筆
A6: 強力降咒 | B6: Bestow Curse,Greater | C6: 等級：吟游詩人 6，牧師 7，宿命 7，法師/術士 8（萬法大全為：牧師 7，法師/術士 8） | D6: 牧師 7；吟游詩人 6；宿命 7；法師/術士 8（萬法大全為：牧師 7 | E6: 吟遊詩人 6；牧師 7；宿命 7；術士 8；法師 8 | F6: 目前錯記為 7 級，括號內是《萬法大全》版本
A7: 閉合傷口 | B7: Close Wounds | C7: 等級：牧師 2（模型手冊為牧師 3、治療師 3） | D7: 牧師 2（模型手冊為牧師 3 | E7: 牧師 2 | F7: 括號內是《模型手冊》版本（牧師 3、治療師 3），不採用
A8: 聖化物品 | B8: Sacred Item | C8: 等級：牧師 4。聖武士 4 | D8: 牧師 4。聖武士 4 | E8: 牧師 4；聖武士 4 | F8: 牧師與聖武士被合成一筆
A9: 堅韌之契 | B9: Stalwart Pact | C9: 等級:牧師 5 Pact 5 | D9: 牧師 5 Pact 5 | E9: 牧師 5；契約 5 | F9: Pact 是契約領域
A10: 心智蜘蛛 | B10: Brain Spider | C10: 等級：牧師 7、心智 7，異怪書為牧師 8 心智 7 | D10: 牧師 7；心智 7；異怪書為牧師 8 心智 7 | E10: 牧師 7；心靈 7 | F10: 多出的一筆是《異怪書》版本，刪除；心智領域已合併到心靈
A11: 祝福精准 | B11: Blessed Aim | C11: 等級：暗黑衛士 1、牧師 1、聖武士 1（完美神力：黑武士 2，牧師 3，聖武士 2） | D11: 牧師 1；牧師 3；暗黑衛士 1；聖武士 1（完美神力：黑武士 2 | E11: 暗黑衛士 1；牧師 1；聖武士 1 | F11: 括號內是《完美神力》版本；多出的牧師 3 也應刪除
A12: 化鰭為趾 | B12: Fins To Feet | C12: 等級：術士/法師 2 （風暴之書）水族領域 2，德魯伊 2 | D12: 德魯伊 2；術士/法師 2 （風暴之書）水族領域 2 | E12: 術士 2；法師 2；水族 2；德魯伊 2 | F12: 術士/法師與水族領域被合成一筆
A13: 災禍術 | B13: Unluck | C13: 等級：吟游詩人 4，術士/法師 4（萬法大全為：吟游詩人 3,術士/法師 3） | D13: 吟游詩人 4；術士/法師 4（萬法大全為：吟游詩人 3 | E13: 吟遊詩人 4；術士 4；法師 4 | F13: 目前錯記為 3 級，括號內是《萬法大全》版本
... A16: 清心之刻 | B16: Moment Clarity | C16: 等級：聖武士 1，好人書為聖武士 2 | D16: 聖武士 1；好人書為聖武士 2 | E16: 聖武士 1 | F16: 多出的一筆是《好人書》版本，刪除

Sheet 學派疑義
A1: 法術 | B1: 英文名稱 | C1: 目前學派文字 | D1: 規則判讀 | E1: 原文英文學派 | F1: 建議學派 | G1: 說明 | H1: 你的備註
A2: 活化物品 | B2: Animate Objects | D2: （無） | F2: 變化 | G2: 學派欄空白；D&D 原書為 Transmutation
A3: 光輝放射 | B3: Brilliant Emanation | D3: （無） | F3: 塑能 | G3: 學派欄空白；待確認，原書應為 Evocation
A4: 寒冰暴怒 | B4: Burst Of Glacial Wrath | C4: 塑能/變化［寒冷］ | D4: 塑能；變化 | F4: 塑能；變化 | G4: 跨學派法術，兩個學派都顯示、都搜得到
A5: 操控死靈 | B5: Control Undead | D5: （無） | F5: 死靈 | G5: 學派欄空白；D&D 原書為 Necromancy
A6: 榮耀之冠 | B6: Crown Of Glory | C6: 附魔系[脅迫]（心靈影響） | D6: 惑控 | F6: 塑能 | G6: 「招魂」是 Evocation 的誤譯，原文為 Evocation
A7: 榮耀之冠 | B7: Crown Of Glory | C7: 招魂 | D7: （無） | E7: Evocation | F7: 塑能 | G7: 「招魂」是 Evocation 的誤譯，原文為 Evocation
A8: 厄難聖甲蟲 | B8: Doom Scarabs | C8: 咒法系/死靈系 | D8: 咒法；死靈 | F8: 咒法；死靈 | G8: 跨學派法術，兩個學派都顯示、都搜得到
A9: 鑄夢術 | B9: Dream Casting | C9: 幻術系（魅影幻覺）[影響心靈]；見下文 | D9: 幻術 | F9: 幻術 | G9: 需要確認
A10: 高等逆電仇殺 | B10: Electric Vengeance,Greater | C10: 法術抗力：可 塑能系 | D10: 塑能 | F10: 塑能 | G10: 學派欄混入「法術抗力：可」，可順便清理
A11: 能量旋渦 | B11: Energy Vortex | C11: 塑能系 [見下]（完美神力[酸，冷，火，電或音波]） | D11: 塑能 | F11: 塑能 | G11: 需要確認
A12: 血色暴怒 | B12: Ferocity Of Sanguine Rage | C12: 變化/預言 | D12: 預言；變化 | F12: 預言；變化 | G12: 跨學派法術，兩個學派都顯示、都搜得到
A13: 赴湯蹈火 | B13: Firestride Exhalation | C13: 咒法（傳送）/塑能［火］ | D13: 咒法；塑能 | F13: 咒法；塑能 | G13: 跨學派法術，兩個學派都顯示、都搜得到
A14: 變化系 | B14: 譯者：3e 的分類？衛生紙大麻抽多了吧„„編輯：同感 | D14: （無） | F14: 變化 | G14: 法術名稱擷取錯誤（中文名變成「變化系」、英文名是譯者註），學派為變化系（傳送）；名稱需在 app 裡手動修正
A15: 鋼鐵骨骼 | B15: Iron Bones | D15: （無） | F15: 變化 | G15: 學派欄空白；待確認，原書應為 Transmutation
A16: 卡魯古爾火焰彈 | B16: Kelgore’s Fire Bolt | C16: 咒法系/塑能系 | D16: 咒法；塑能 | F16: 咒法；塑能 | G16: 跨學派法術，兩個學派都顯示、都搜得到
A17: 卡魯古爾墓窖寒霧 | B17: Kelgore’s Grave Mist | C17: 咒法系/死靈系 | D17: 咒法；死靈 | F17: 咒法；死靈 | G17: 跨學派法術，兩個學派都顯示、都搜得到
A18: 威震天空 | B18: Lord Of The Sky | C18: 塑能［電］/變化 | D18: 塑能；變化 | F18: 塑能；變化 | G18: 跨學派法術，兩個學派都顯示、都搜得到
A19: 飛沙走石 | B19: Passage Of The Shifting Sand | C19: 變化系/塑能系［氣］ | D19: 塑能；變化 | F19: 塑能；變化 | G19: 跨學派法術，兩個學派都顯示、都搜得到
A20: 異界抗力 | B20: Planar Tolerance | D20: （無） | F20: 防護 | G20: 學派欄空白；D&D 原書為 Abjuration
A21: 古時糟粕 | B21: Rot Of Ages | C21: 咒法系（創造）/死靈系 | D21: 咒法；死靈 | F21: 咒法；死靈 | G21: 跨學派法術，兩個學派都顯示、都搜得到
A22: 幻術系 | B22: Shadow | D22: （無） | E22: Evocation | F22: 幻術 | G22: 法術名稱擷取錯誤（中文名變成「幻術系」），應是幽影塑能術（Shadow Evocation）
A23: 幻術系 | B23: Shadow | D23: （無） | F23: 幻術 | G23: 法術名稱擷取錯誤（中文名變成「幻術系」），應是高等幽影塑能術（Greater Shadow Evocation）
A24: 陰影爆破 | B24: SHADOWBLAST | C24: 招魂 | D24: （無） | E24: Evocation | F24: 塑能 | G24: 「招魂」是 Evocation 的誤譯
A25: 碎片風暴 | B25: SHARD STORM | C25: 招魂 | D25: （無） | E25: Evocation | F25: 塑能 | G25: 「招魂」是 Evocation 的誤譯
A26: 碎地術 | B26: SHATTERFLOOR | C26: 招魂 | D26: （無） | E26: Evocation | F26: 塑能 | G26: 「招魂」是 Evocation 的誤譯
A27: 結界之盾 | B27: Shield Of Warding | C27: 放棄 | D27: （無） | E27: Abjuration | F27: 防護 | G27: 「放棄」是 Abjuration 的誤譯，原文為 Abjuration
A28: 火焰罩衣 | B28: SHROUD OF FLAME | C28: 招魂 | D28: （無） | E28: Evocation | F28: 塑能 | G28: 「招魂」是 Evocation 的誤譯
A29: 徵兆術 | B29: SIGN | C29: 魅力 | D29: （無） | E29: Enchantment | F29: 惑控 | G29: 「魅力」是 Enchantment 的誤譯，原文為 Enchantment
A30: 掌摑之手 | B30: SLAPPING HAND | C30: 招魂 | D30: （無） | E30: Evocation | F30: 塑能 | G30: 「招魂」是 Evocation 的誤譯
A31: 裂魔消解 | B31: Slashing Dispel | C31: 防護/塑能系 | D31: 防護；塑能 | F31: 防護；塑能 | G31: 跨學派法術，兩個學派都顯示、都搜得到
A32: 暴蛛之禍 | B32: Spider Plague | C32: 咒法系 （召喚） [見下文] | D32: 咒法 | F32: 咒法 | G32: 需要確認
A33: 沙塵風暴 | B33: Storm Mote | C33: 10 10 塑能系 | D33: 塑能 | F33: 塑能 | G33: 學派欄開頭混入「10 10」，可順便清理
A34: 全知之眼 | B34: Vision Of The Omniscient Eye | C34: 預言/塑能［光］ | D34: 預言；塑能 | F34: 預言；塑能 | G34: 跨學派法術，兩個學派都顯示、都搜得到
A35: 腋生清風 | B35: Wingblast | C35: 塑能［氣］/變化 | D35: 塑能；變化 | F35: 塑能；變化 | G35: 跨學派法術，兩個學派都顯示、都搜得到

Sheet 標準職業表
A1: 標準名稱 | B1: 類別 | C1: 英文名稱 | D1: 對應寫法數 | E1: 等級資料筆數 | F1: 說明
A2: 術士 | B2: 職業 | C2: Sorcerer | D2: =SUMPRODUCT(--ISNUMBER(SEARCH("；"&$A2&"；","；"&SUBSTITUTE('職業對照'!$G$2:$G$208,";","；")&"；"))) | E2: =SUMPRODUCT(ISNUMBER(SEARCH("；"&$A2&"；","；"&SUBSTITUTE('職業對照'!$G$2:$G$208,";","；")&"；"))*'職業對照'!$C$2:$C$208)
A3: 法師 | B3: 職業 | C3: Wizard | D3: =SUMPRODUCT(--ISNUMBER(SEARCH("；"&$A3&"；","；"&SUBSTITUTE('職業對照'!$G$2:$G$208,";","；")&"；"))) | E3: =SUMPRODUCT(ISNUMBER(SEARCH("；"&$A3&"；","；"&SUBSTITUTE('職業對照'!$G$2:$G$208,";","；")&"；"))*'職業對照'!$C$2:$C$208)
A4: 牧師 | B4: 職業 | C4: Cleric | D4: =SUMPRODUCT(--ISNUMBER(SEARCH("；"&$A4&"；","；"&SUBSTITUTE('職業對照'!$G$2:$G$208,";","；")&"；"))) | E4: =SUMPRODUCT(ISNUMBER(SEARCH("；"&$A4&"；","；"&SUBSTITUTE('職業對照'!$G$2:$G$208,";","；")&"；"))*'職業對照'!$C$2:$C$208)
A5: 德魯伊 | B5: 職業 | C5: Druid | D5: =SUMPRODUCT(--ISNUMBER(SEARCH("；"&$A5&"；","；"&SUBSTITUTE('職業對照'!$G$2:$G$208,";","；")&"；"))) | E5: =SUMPRODUCT(ISNUMBER(SEARCH("；"&$A5&"；","；"&SUBSTITUTE('職業對照'!$G$2:$G$208,";","；")&"；"))*'職業對照'!$C$2:$C$208)
A6: 吟遊詩人 | B6: 職業 | C6: Bard | D6: =SUMPRODUCT(--ISNUMBER(SEARCH("；"&$A6&"；","；"&SUBSTITUTE('職業對照'!$G$2:$G$208,";","；")&"；"))) | E6: =SUMPRODUCT(ISNUMBER(SEARCH("；"&$A6&"；","；"&SUBSTITUTE('職業對照'!$G$2:$G$208,";","；")&"；"))*'職業對照'!$C$2:$C$208)
A7: 遊俠 | B7: 職業 | C7: Ranger | D7: =SUMPRODUCT(--ISNUMBER(SEARCH("；"&$A7&"；","；"&SUBSTITUTE('職業對照'!$G$2:$G$208,";","；")&"；"))) | E7: =SUMPRODUCT(ISNUMBER(SEARCH("；"&$A7&"；","；"&SUBSTITUTE('職業對照'!$G$2:$G$208,";","；")&"；"))*'職業對照'!$C$2:$C$208) | F7: 原文另有「巡林客」譯名
A8: 聖武士 | B8: 職業 | C8: Paladin | D8: =SUMPRODUCT(--ISNUMBER(SEARCH("；"&$A8&"；","；"&SUBSTITUTE('職業對照'!$G$2:$G$208,";","；")&"；"))) | E8: =SUMPRODUCT(ISNUMBER(SEARCH("；"&$A8&"；","；"&SUBSTITUTE('職業對照'!$G$2:$G$208,";","；")&"；"))*'職業對照'!$C$2:$C$208)
A9: 巫覡 | B9: 職業 | C9: Wu Jen | D9: =SUMPRODUCT(--ISNUMBER(SEARCH("；"&$A9&"；","；"&SUBSTITUTE('職業對照'!$G$2:$G$208,";","；")&"；"))) | E9: =SUMPRODUCT(ISNUMBER(SEARCH("；"&$A9&"；","；"&SUBSTITUTE('職業對照'!$G$2:$G$208,";","；")&"；"))*'職業對照'!$C$2:$C$208) | F9: 巫覡（Wu Jen），等級備註中的金木水火土是它的元素
A10: 刺客 | B10: 職業 | C10: Assassin | D10: =SUMPRODUCT(--ISNUMBER(SEARCH("；"&$A10&"；","；"&SUBSTITUTE('職業對照'!$G$2:$G$208,";","；")&"；"))) | E10: =SUMPRODUCT(ISNUMBER(SEARCH("；"&$A10&"；","；"&SUBSTITUTE('職業對照'!$G$2:$G$208,";","；")&"；"))*'職業對照'!$C$2:$C$208)
A11: 暗黑衛士 | B11: 職業 | C11: Blackguard | D11: =SUMPRODUCT(--ISNUMBER(SEARCH("；"&$A11&"；","；"&SUBSTITUTE('職業對照'!$G$2:$G$208,";","；")&"；"))) | E11: =SUMPRODUCT(ISNUMBER(SEARCH("；"&$A11&"；","；"&SUBSTITUTE('職業對照'!$G$2:$G$208,";","；")&"；"))*'職業對照'!$C$2:$C$208) | F11: 合併了黑暗衛士、黑衛、黑衛士、黑暗守衛
A12: 暮刃 | B12: 職業 | C12: Duskblade | D12: =SUMPRODUCT(--ISNUMBER(SEARCH("；"&$A12&"；","；"&SUBSTITUTE('職業對照'!$G$2:$G$208,";","；")&"；"))) | E12: =SUMPRODUCT(ISNUMBER(SEARCH("；"&$A12&"；","；"&SUBSTITUTE('職業對照'!$G$2:$G$208,";","；")&"；"))*'職業對照'!$C$2:$C$208) | F12: 合併了薄暮劍士
A13: 戰法師 | B13: 職業 | C13: Warmage | D13: =SUMPRODUCT(--ISNUMBER(SEARCH("；"&$A13&"；","；"&SUBSTITUTE('職業對照'!$G$2:$G$208,";","；")&"；"))) | E13: =SUMPRODUCT(ISNUMBER(SEARCH("；"&$A13&"；","；"&SUBSTITUTE('職業對照'!$G$2:$G$208,";","；")&"；"))*'職業對照'!$C$2:$C$208)
A14: 和平使者 | B14: 職業 | C14: Apostle of Peace | D14: =SUMPRODUCT(--ISNUMBER(SEARCH("；"&$A14&"；","；"&SUBSTITUTE('職業對照'!$G$2:$G$208,";","；")&"；"))) | E14: =SUMPRODUCT(ISNUMBER(SEARCH("；"&$A14&"；","；"&SUBSTITUTE('職業對照'!$G$2:$G$208,";","；")&"；"))*'職業對照'!$C$2:$C$208)
A15: 欺瞞者 | B15: 職業 | C15: Beguiler | D15: =SUMPRODUCT(--ISNUMBER(SEARCH("；"&$A15&"；","；"&SUBSTITUTE('職業對照'!$G$2:$G$208,";","；")&"；"))) | E15: =SUMPRODUCT(ISNUMBER(SEARCH("；"&$A15&"；","；"&SUBSTITUTE('職業對照'!$G$2:$G$208,";","；")&"；"))*'職業對照'!$C$2:$C$208)
A16: 魔劍客 | B16: 職業 | C16: Hexblade | D16: =SUMPRODUCT(--ISNUMBER(SEARCH("；"&$A16&"；","；"&SUBSTITUTE('職業對照'!$G$2:$G$208,";","；")&"；"))) | E16: =SUMPRODUCT(ISNUMBER(SEARCH("；"&$A16&"；","；"&SUBSTITUTE('職業對照'!$G$2:$G$208,";","；")&"；"))*'職業對照'!$C$2:$C$208) | F16: 「魔劍」1 筆也歸到這裡；合併了魔劍士
A17: 崇善秘法師 | B17: 職業 | D17: =SUMPRODUCT(--ISNUMBER(SEARCH("；"&$A17&"；","；"&SUBSTITUTE('職業對照'!$G$2:$G$208,";","；")&"；"))) | E17: =SUMPRODUCT(ISNUMBER(SEARCH("；"&$A17&"；","；"&SUBSTITUTE('職業對照'!$G$2:$G$208,";","；")&"；"))*'職業對照'!$C$2:$C$208) | F17: 進階職業
A18: 機關術士 | B18: 職業 | C18: Artificer | D18: =SUMPRODUCT(--ISNUMBER(SEARCH("；"&$A18&"；","；"&SUBSTITUTE('職業對照'!$G$2:$G$208,";","；")&"；"))) | E18: =SUMPRODUCT(ISNUMBER(SEARCH("；"&$A18&"；","；"&SUBSTITUTE('職業對照'!$G$2:$G$208,";","；")&"；"))*'職業對照'!$C$2:$C$208)
A19: 修驗者 | B19: 職業 | C19: Shugenja | D19: =SUMPRODUCT(--ISNUMBER(SEARCH("；"&$A19&"；","；"&SUBSTITUTE('職業對照'!$G$2:$G$208,";","；")&"；"))) | E19: =SUMPRODUCT(ISNUMBER(SEARCH("；"&$A19&"；","；"&SUBSTITUTE('職業對照'!$G$2:$G$208,";","；")&"；"))*'職業對照'!$C$2:$C$208) | F19: 修驗者（Shugenja）；合併了導師
A20: 格溫哈威夫鬥士 | B20: 職業 | C20: Champion of Gwynharwyf | D20: =SUMPRODUCT(--ISNUMBER(SEARCH("；"&$A20&"；","；"&SUBSTITUTE('職業對照'!$G$2:$G$208,";","；")&"；"))) | E20: =SUMPRODUCT(ISNUMBER(SEARCH("；"&$A20&"；","；"&SUBSTITUTE('職業對照'!$G$2:$G$208,";","；")&"；"))*'職業對照'!$C$2:$C$208)
A21: 法爾賴恩的愛人 | B21: 職業 | C21: Beloved of Valarian | D21: =SUMPRODUCT(--ISNUMBER(SEARCH("；"&$A21&"；","；"&SUBSTITUTE('職業對照'!$G$2:$G$208,";","；")&"；"))) | E21: =SUMPRODUCT(ISNUMBER(SEARCH("；"&$A21&"；","；"&SUBSTITUTE('職業對照'!$G$2:$G$208,";","；")&"；"))*'職業對照'!$C$2:$C$208)
A22: 信使 | B22: 職業 | D22: =SUMPRODUCT(--ISNUMBER(SEARCH("；"&$A22&"；","；"&SUBSTITUTE('職業對照'!$G$2:$G$208,";","；")&"；"))) | E22: =SUMPRODUCT(ISNUMBER(SEARCH("；"&$A22&"；","；"&SUBSTITUTE('職業對照'!$G$2:$G$208,";","；")&"；"))*'職業對照'!$C$2:$C$208)
A23: 多米艾爾的屠戮者 | B23: 職業 | C23: Slayer of Domiel | D23: =SUMPRODUCT(--ISNUMBER(SEARCH("；"&$A23&"；","；"&SUBSTITUTE('職業對照'!$G$2:$G$208,";","；")&"；"))) | E23: =SUMPRODUCT(ISNUMBER(SEARCH("；"&$A23&"；","；"&SUBSTITUTE('職業對照'!$G$2:$G$208,";","；")&"；"))*'職業對照'!$C$2:$C$208)
A24: 巴拉契艾爾的密使 | B24: 職業 | C24: Emissary of Barachiel | D24: =SUMPRODUCT(--ISNUMBER(SEARCH("；"&$A24&"；","；"&SUBSTITUTE('職業對照'!$G$2:$G$208,";","；")&"；"))) | E24: =SUMPRODUCT(ISNUMBER(SEARCH("；"&$A24&"；","；"&SUBSTITUTE('職業對照'!$G$2:$G$208,";","；")&"；"))*'職業對照'!$C$2:$C$208)
A25: 巴哈姆特封臣 | B25: 職業 | C25: Vassal of Bahamut | D25: =SUMPRODUCT(--ISNUMBER(SEARCH("；"&$A25&"；","；"&SUBSTITUTE('職業對照'!$G$2:$G$208,";","；")&"；"))) | E25: =SUMPRODUCT(ISNUMBER(SEARCH("；"&$A25&"；","；"&SUBSTITUTE('職業對照'!$G$2:$G$208,";","；")&"；"))*'職業對照'!$C$2:$C$208)
A26: 治療師 | B26: 職業 | C26: Healer | D26: =SUMPRODUCT(--ISNUMBER(SEARCH("；"&$A26&"；","；"&SUBSTITUTE('職業對照'!$G$2:$G$208,";","；")&"；"))) | E26: =SUMPRODUCT(ISNUMBER(SEARCH("；"&$A26&"；","；"&SUBSTITUTE('職業對照'!$G$2:$G$208,";","；")&"；"))*'職業對照'!$C$2:$C$208)
A27: 天界騎士 | B27: 職業 | D27: =SUMPRODUCT(--ISNUMBER(SEARCH("；"&$A27&"；","；"&SUBSTITUTE('職業對照'!$G$2:$G$208,";","；")&"；"))) | E27: =SUMPRODUCT(ISNUMBER(SEARCH("；"&$A27&"；","；"&SUBSTITUTE('職業對照'!$G$2:$G$208,";","；")&"；"))*'職業對照'!$C$2:$C$208) | F27: 天界騎士（Celestia）
A28: 保護 | B28: 領域 | C28: Protection | D28: =SUMPRODUCT(--ISNUMBER(SEARCH("；"&$A28&"；","；"&SUBSTITUTE('職業對照'!$G$2:$G$208,";","；")&"；"))) | E28: =SUMPRODUCT(ISNUMBER(SEARCH("；"&$A28&"；","；"&SUBSTITUTE('職業對照'!$G$2:$G$208,";","；")&"；"))*'職業對照'!$C$2:$C$208)
A29: 力量 | B29: 領域 | C29: Strength | D29: =SUMPRODUCT(--ISNUMBER(SEARCH("；"&$A29&"；","；"&SUBSTITUTE('職業對照'!$G$2:$G$208,";","；")&"；"))) | E29: =SUMPRODUCT(ISNUMBER(SEARCH("；"&$A29&"；","；"&SUBSTITUTE('職業對照'!$G$2:$G$208,";","；")&"；"))*'職業對照'!$C$2:$C$208) | F29: 合併了力
A30: 土 | B30: 領域 | C30: Earth | D30: =SUMPRODUCT(--ISNUMBER(SEARCH("；"&$A30&"；","；"&SUBSTITUTE('職業對照'!$G$2:$G$208,";","；")&"；"))) | E30: =SUMPRODUCT(ISNUMBER(SEARCH("；"&$A30&"；","；"&SUBSTITUTE('職業對照'!$G$2:$G$208,";","；")&"；"))*'職業對照'!$C$2:$C$208)
A31: 城市 | B31: 領域 | C31: City | D31: =SUMPRODUCT(--ISNUMBER(SEARCH("；"&$A31&"；","；"&SUBSTITUTE('職業對照'!$G$2:$G$208,";","；")&"；"))) | E31: =SUMPRODUCT(ISNUMBER(SEARCH("；"&$A31&"；","；"&SUBSTITUTE('職業對照'!$G$2:$G$208,";","；")&"；"))*'職業對照'!$C$2:$C$208)
A32: 太陽 | B32: 領域 | C32: Sun | D32: =SUMPRODUCT(--ISNUMBER(SEARCH("；"&$A32&"；","；"&SUBSTITUTE('職業對照'!$G$2:$G$208,";","；")&"；"))) | E32: =SUMPRODUCT(ISNUMBER(SEARCH("；"&$A32&"；","；"&SUBSTITUTE('職業對照'!$G$2:$G$208,";","；")&"；"))*'職業對照'!$C$2:$C$208)
A33: 戰爭 | B33: 領域 | C33: War | D33: =SUMPRODUCT(--ISNUMBER(SEARCH("；"&$A33&"；","；"&SUBSTITUTE('職業對照'!$G$2:$G$208,";","；")&"；"))) | E33: =SUMPRODUCT(ISNUMBER(SEARCH("；"&$A33&"；","；"&SUBSTITUTE('職業對照'!$G$2:$G$208,";","；")&"；"))*'職業對照'!$C$2:$C$208)
A34: 旅行 | B34: 領域 | C34: Travel | D34: =SUMPRODUCT(--ISNUMBER(SEARCH("；"&$A34&"；","；"&SUBSTITUTE('職業對照'!$G$2:$G$208,";","；")&"；"))) | E34: =SUMPRODUCT(ISNUMBER(SEARCH("；"&$A34&"；","；"&SUBSTITUTE('職業對照'!$G$2:$G$208,";","；")&"；"))*'職業對照'!$C$2:$C$208)
A35: 植物 | B35: 領域 | C35: Plant | D35: =SUMPRODUCT(--ISNUMBER(SEARCH("；"&$A35&"；","；"&SUBSTITUTE('職業對照'!$G$2:$G$208,";","；")&"；"))) | E35: =SUMPRODUCT(ISNUMBER(SEARCH("；"&$A35&"；","；"&SUBSTITUTE('職業對照'!$G$2:$G$208,";","；")&"；"))*'職業對照'!$C$2:$C$208)
A36: 機運 | B36: 領域 | C36: Luck | D36: =SUMPRODUCT(--ISNUMBER(SEARCH("；"&$A36&"；","；"&SUBSTITUTE('職業對照'!$G$2:$G$208,";","；")&"；"))) | E36: =SUMPRODUCT(ISNUMBER(SEARCH("；"&$A36&"；","；"&SUBSTITUTE('職業對照'!$G$2:$G$208,";","；")&"；"))*'職業對照'!$C$2:$C$208)
A37: 死亡 | B37: 領域 | C37: Death | D37: =SUMPRODUCT(--ISNUMBER(SEARCH("；"&$A37&"；","；"&SUBSTITUTE('職業對照'!$G$2:$G$208,";","；")&"；"))) | E37: =SUMPRODUCT(ISNUMBER(SEARCH("；"&$A37&"；","；"&SUBSTITUTE('職業對照'!$G$2:$G$208,";","；")&"；"))*'職業對照'!$C$2:$C$208)
A38: 水 | B38: 領域 | C38: Water | D38: =SUMPRODUCT(--ISNUMBER(SEARCH("；"&$A38&"；","；"&SUBSTITUTE('職業對照'!$G$2:$G$208,";","；")&"；"))) | E38: =SUMPRODUCT(ISNUMBER(SEARCH("；"&$A38&"；","；"&SUBSTITUTE('職業對照'!$G$2:$G$208,";","；")&"；"))*'職業對照'!$C$2:$C$208)
A39: 混亂 | B39: 領域 | C39: Chaos | D39: =SUMPRODUCT(--ISNUMBER(SEARCH("；"&$A39&"；","；"&SUBSTITUTE('職業對照'!$G$2:$G$208,";","；")&"；"))) | E39: =SUMPRODUCT(ISNUMBER(SEARCH("；"&$A39&"；","；"&SUBSTITUTE('職業對照'!$G$2:$G$208,";","；")&"；"))*'職業對照'!$C$2:$C$208) | F39: 合併了混沌
A40: 火 | B40: 領域 | C40: Fire | D40: =SUMPRODUCT(--ISNUMBER(SEARCH("；"&$A40&"；","；"&SUBSTITUTE('職業對照'!$G$2:$G$208,";","；")&"；"))) | E40: =SUMPRODUCT(ISNUMBER(SEARCH("；"&$A40&"；","；"&SUBSTITUTE('職業對照'!$G$2:$G$208,";","；")&"；"))*'職業對照'!$C$2:$C$208)
...
